2024-09-25T08:09:00 {"cpu": 0.25537109375, "cpu_total": 12, "cpu_usage": 0.021280924479166668, "memory": 3613.0, "memory_total": 4845.0, "memory_usage": 0.7457172342621259, "pipeline_run_id": 2, "pipeline_schedule_id": 1, "pipeline_uuid": "wisr_challenge_pipeline", "hostname": "d372c474b7a1", "level": "INFO", "message": "Pipeline wisr_challenge_pipeline for run 2 in schedule 1 is alive.", "timestamp": 1727251740.052908, "uuid": "1d27e4d68a794de8afd5e5ae9e66525b"}
2024-09-25T08:09:00 {"cpu": 0.25537109375, "cpu_total": 12, "cpu_usage": 0.021280924479166668, "memory": 3646.0, "memory_total": 4845.0, "memory_usage": 0.7525283797729618, "pipeline_run_id": 2, "pipeline_schedule_id": 1, "pipeline_uuid": "wisr_challenge_pipeline", "hostname": "d372c474b7a1", "level": "INFO", "message": "Pipeline wisr_challenge_pipeline for run 2 in schedule 1 is alive.", "timestamp": 1727251740.493477, "uuid": "642a659a212347228e4adfcaa4214b16"}
2024-09-25T08:09:00 {"block_run_id": 22, "block_uuid": "test_connection", "pipeline_run_id": 2, "pipeline_schedule_id": 1, "pipeline_uuid": "wisr_challenge_pipeline", "hostname": "d372c474b7a1", "level": "INFO", "message": "Execute PipelineRun 2, BlockRun 22: pipeline wisr_challenge_pipeline block test_connection", "timestamp": 1727251740.497692, "uuid": "a1e88f857f8a46dc91166a4dd141d85d"}
2024-09-25T08:09:01 {"block_run_id": 22, "block_uuid": "test_connection", "pipeline_run_id": 2, "pipeline_schedule_id": 1, "pipeline_uuid": "wisr_challenge_pipeline", "hostname": "d372c474b7a1", "level": "INFO", "message": "BlockRun 22 (block_uuid: test_connection) completes.", "timestamp": 1727251741.260392, "uuid": "50ad7af9cc6845dd9f4ea9a12f6f39fb"}
2024-09-25T08:09:01 {"block_run_id": 23, "block_uuid": "departments", "pipeline_run_id": 2, "pipeline_schedule_id": 1, "pipeline_uuid": "wisr_challenge_pipeline", "hostname": "d372c474b7a1", "level": "INFO", "message": "Execute PipelineRun 2, BlockRun 23: pipeline wisr_challenge_pipeline block departments", "timestamp": 1727251741.54711, "uuid": "8518a3e0eebc44a2b5006735710a9f8c"}
2024-09-25T08:09:01 {"block_run_id": 23, "block_uuid": "departments", "pipeline_run_id": 2, "pipeline_schedule_id": 1, "pipeline_uuid": "wisr_challenge_pipeline", "hostname": "d372c474b7a1", "level": "INFO", "message": "BlockRun 23 (block_uuid: departments) completes.", "timestamp": 1727251741.961505, "uuid": "631c6fed74d6446b9393f907978b50a0"}
2024-09-25T08:09:09 {"cpu": 0.25244140625, "cpu_total": 12, "cpu_usage": 0.021036783854166668, "memory": 3615.0, "memory_total": 4845.0, "memory_usage": 0.7461300309597523, "pipeline_run_id": 2, "pipeline_schedule_id": 1, "pipeline_uuid": "wisr_challenge_pipeline", "hostname": "d372c474b7a1", "level": "INFO", "message": "Pipeline wisr_challenge_pipeline for run 2 in schedule 1 is alive.", "timestamp": 1727251749.83385, "uuid": "ee782851402c40448490108dd08a7427"}
2024-09-25T08:09:10 {"block_run_id": 24, "block_uuid": "export_departments", "pipeline_run_id": 2, "pipeline_schedule_id": 1, "pipeline_uuid": "wisr_challenge_pipeline", "hostname": "d372c474b7a1", "level": "INFO", "message": "Execute PipelineRun 2, BlockRun 24: pipeline wisr_challenge_pipeline block export_departments", "timestamp": 1727251750.161679, "uuid": "e9470d646c924e2bbc92ac7f43c10529"}
2024-09-25T08:09:11 {"block_run_id": 33, "block_uuid": "load_titles", "pipeline_run_id": 2, "pipeline_schedule_id": 1, "pipeline_uuid": "wisr_challenge_pipeline", "hostname": "d372c474b7a1", "level": "INFO", "message": "Execute PipelineRun 2, BlockRun 33: pipeline wisr_challenge_pipeline block load_titles", "timestamp": 1727251751.260583, "uuid": "f2a41b738d544fd98d445da3f32320b1"}
2024-09-25T08:09:11 {"block_run_id": 24, "block_uuid": "export_departments", "pipeline_run_id": 2, "pipeline_schedule_id": 1, "pipeline_uuid": "wisr_challenge_pipeline", "hostname": "d372c474b7a1", "level": "EXCEPTION", "message": "BlockRun 24 (block_uuid: export_departments) failed.", "timestamp": 1727251751.726846, "uuid": "89f8f375fb674588bfedb1d41ac47272", "error": "Traceback (most recent call last):\n  File \"/usr/local/lib/python3.10/site-packages/mysql/connector/connection_cext.py\", line 639, in cmd_query\n    self._cmysql.query(\n_mysql_connector.MySQLInterfaceError: Table 'departments' already exists\n\nThe above exception was the direct cause of the following exception:\n\nTraceback (most recent call last):\n  File \"/usr/local/lib/python3.10/site-packages/mage_ai/data_preparation/executors/block_executor.py\", line 647, in execute\n    result = __execute_with_retry()\n  File \"/usr/local/lib/python3.10/site-packages/mage_ai/shared/retry.py\", line 54, in retry_func\n    raise e\n  File \"/usr/local/lib/python3.10/site-packages/mage_ai/shared/retry.py\", line 38, in retry_func\n    return func(*args, **kwargs)\n  File \"/usr/local/lib/python3.10/site-packages/mage_ai/data_preparation/executors/block_executor.py\", line 621, in __execute_with_retry\n    return self._execute(\n  File \"/usr/local/lib/python3.10/site-packages/mage_ai/data_preparation/executors/block_executor.py\", line 1154, in _execute\n    result = self.block.execute_sync(\n  File \"/usr/local/lib/python3.10/site-packages/mage_ai/data_preparation/models/block/__init__.py\", line 1691, in execute_sync\n    return __execute()\n  File \"/usr/local/lib/python3.10/site-packages/mage_ai/data_preparation/models/block/__init__.py\", line 1668, in __execute\n    raise err\n  File \"/usr/local/lib/python3.10/site-packages/mage_ai/data_preparation/models/block/__init__.py\", line 1570, in __execute\n    output = self.execute_block(\n  File \"/usr/local/lib/python3.10/site-packages/mage_ai/data_preparation/models/block/__init__.py\", line 1910, in execute_block\n    outputs = self._execute_block(\n  File \"/usr/local/lib/python3.10/site-packages/mage_ai/data_preparation/models/block/sql/__init__.py\", line 749, in _execute_block\n    return execute_sql_code(\n  File \"/usr/local/lib/python3.10/site-packages/mage_ai/data_preparation/models/block/sql/__init__.py\", line 414, in execute_sql_code\n    return execute_raw_sql(\n  File \"/usr/local/lib/python3.10/site-packages/mage_ai/data_preparation/models/block/sql/__init__.py\", line 722, in execute_raw_sql\n    results = loader.execute_queries(\n  File \"/usr/local/lib/python3.10/site-packages/mage_ai/io/sql.py\", line 164, in execute_queries\n    result = cursor.execute(query, **variables)\n  File \"/usr/local/lib/python3.10/site-packages/mysql/connector/cursor_cext.py\", line 330, in execute\n    result = self._cnx.cmd_query(\n  File \"/usr/local/lib/python3.10/site-packages/mysql/connector/opentelemetry/context_propagation.py\", line 86, in wrapper\n    result = method(cnx, *args, **kwargs)\n  File \"/usr/local/lib/python3.10/site-packages/mysql/connector/connection_cext.py\", line 647, in cmd_query\n    raise get_mysql_exception(\nmysql.connector.errors.ProgrammingError: 1050 (42S01): Table 'departments' already exists\n", "error_stack": ["  File \"/usr/local/bin/mage\", line 8, in <module>\n    sys.exit(app())\n", "  File \"/usr/local/lib/python3.10/site-packages/typer/main.py\", line 311, in __call__\n    return get_command(self)(*args, **kwargs)\n", "  File \"/usr/local/lib/python3.10/site-packages/click/core.py\", line 1130, in __call__\n    return self.main(*args, **kwargs)\n", "  File \"/usr/local/lib/python3.10/site-packages/typer/core.py\", line 778, in main\n    return _main(\n", "  File \"/usr/local/lib/python3.10/site-packages/typer/core.py\", line 216, in _main\n    rv = self.invoke(ctx)\n", "  File \"/usr/local/lib/python3.10/site-packages/click/core.py\", line 1657, in invoke\n    return _process_result(sub_ctx.command.invoke(sub_ctx))\n", "  File \"/usr/local/lib/python3.10/site-packages/click/core.py\", line 1404, in invoke\n    return ctx.invoke(self.callback, **ctx.params)\n", "  File \"/usr/local/lib/python3.10/site-packages/click/core.py\", line 760, in invoke\n    return __callback(*args, **kwargs)\n", "  File \"/usr/local/lib/python3.10/site-packages/typer/main.py\", line 683, in wrapper\n    return callback(**use_params)  # type: ignore\n", "  File \"/usr/local/lib/python3.10/site-packages/mage_ai/cli/main.py\", line 147, in start\n    start_server(\n", "  File \"/usr/local/lib/python3.10/site-packages/mage_ai/server/server.py\", line 800, in start_server\n    scheduler_manager.start_scheduler()\n", "  File \"/usr/local/lib/python3.10/site-packages/mage_ai/server/scheduler_manager.py\", line 106, in start_scheduler\n    proc.start()\n", "  File \"/usr/local/lib/python3.10/multiprocessing/process.py\", line 121, in start\n    self._popen = self._Popen(self)\n", "  File \"/usr/local/lib/python3.10/multiprocessing/context.py\", line 224, in _Popen\n    return _default_context.get_context().Process._Popen(process_obj)\n", "  File \"/usr/local/lib/python3.10/multiprocessing/context.py\", line 281, in _Popen\n    return Popen(process_obj)\n", "  File \"/usr/local/lib/python3.10/multiprocessing/popen_fork.py\", line 19, in __init__\n    self._launch(process_obj)\n", "  File \"/usr/local/lib/python3.10/multiprocessing/popen_fork.py\", line 71, in _launch\n    code = process_obj._bootstrap(parent_sentinel=child_r)\n", "  File \"/usr/local/lib/python3.10/multiprocessing/process.py\", line 314, in _bootstrap\n    self.run()\n", "  File \"/usr/local/lib/python3.10/multiprocessing/process.py\", line 108, in run\n    self._target(*self._args, **self._kwargs)\n", "  File \"/usr/local/lib/python3.10/site-packages/mage_ai/orchestration/db/process.py\", line 15, in start_session_and_run\n    results = target(*args)\n", "  File \"/usr/local/lib/python3.10/site-packages/mage_ai/server/scheduler_manager.py\", line 58, in run_scheduler\n    LoopTimeTrigger().start()\n", "  File \"/usr/local/lib/python3.10/site-packages/mage_ai/orchestration/triggers/loop_time_trigger.py\", line 14, in start\n    self.run()\n", "  File \"/usr/local/lib/python3.10/site-packages/mage_ai/orchestration/triggers/time_trigger.py\", line 11, in run\n    schedule_all()\n", "  File \"/usr/local/lib/python3.10/site-packages/mage_ai/orchestration/pipeline_scheduler_original.py\", line 1731, in schedule_all\n    PipelineScheduler(r).schedule()\n", "  File \"/usr/local/lib/python3.10/site-packages/mage_ai/orchestration/db/__init__.py\", line 158, in func_with_rollback\n    return func(*args, **kwargs)\n", "  File \"/usr/local/lib/python3.10/site-packages/mage_ai/orchestration/pipeline_scheduler_original.py\", line 334, in schedule\n    self.__schedule_blocks(block_runs)\n", "  File \"/usr/local/lib/python3.10/site-packages/mage_ai/orchestration/pipeline_scheduler_original.py\", line 641, in __schedule_blocks\n    job_manager.add_job(\n", "  File \"/usr/local/lib/python3.10/site-packages/mage_ai/orchestration/job_manager.py\", line 20, in add_job\n    self.queue.enqueue(job_id, target, *args, **kwargs)\n", "  File \"/usr/local/lib/python3.10/site-packages/mage_ai/orchestration/queue/process_queue.py\", line 121, in enqueue\n    self.start_worker_pool()\n", "  File \"/usr/local/lib/python3.10/site-packages/mage_ai/orchestration/queue/process_queue.py\", line 198, in start_worker_pool\n    self.worker_pool_proc.start()\n", "  File \"/usr/local/lib/python3.10/multiprocessing/process.py\", line 121, in start\n    self._popen = self._Popen(self)\n", "  File \"/usr/local/lib/python3.10/multiprocessing/context.py\", line 224, in _Popen\n    return _default_context.get_context().Process._Popen(process_obj)\n", "  File \"/usr/local/lib/python3.10/multiprocessing/context.py\", line 281, in _Popen\n    return Popen(process_obj)\n", "  File \"/usr/local/lib/python3.10/multiprocessing/popen_fork.py\", line 19, in __init__\n    self._launch(process_obj)\n", "  File \"/usr/local/lib/python3.10/multiprocessing/popen_fork.py\", line 71, in _launch\n    code = process_obj._bootstrap(parent_sentinel=child_r)\n", "  File \"/usr/local/lib/python3.10/multiprocessing/process.py\", line 314, in _bootstrap\n    self.run()\n", "  File \"/usr/local/lib/python3.10/multiprocessing/process.py\", line 108, in run\n    self._target(*self._args, **self._kwargs)\n", "  File \"/usr/local/lib/python3.10/site-packages/mage_ai/orchestration/queue/process_queue.py\", line 351, in poll_job_and_execute\n    worker.start()\n", "  File \"/usr/local/lib/python3.10/multiprocessing/process.py\", line 121, in start\n    self._popen = self._Popen(self)\n", "  File \"/usr/local/lib/python3.10/multiprocessing/context.py\", line 224, in _Popen\n    return _default_context.get_context().Process._Popen(process_obj)\n", "  File \"/usr/local/lib/python3.10/multiprocessing/context.py\", line 281, in _Popen\n    return Popen(process_obj)\n", "  File \"/usr/local/lib/python3.10/multiprocessing/popen_fork.py\", line 19, in __init__\n    self._launch(process_obj)\n", "  File \"/usr/local/lib/python3.10/multiprocessing/popen_fork.py\", line 71, in _launch\n    code = process_obj._bootstrap(parent_sentinel=child_r)\n", "  File \"/usr/local/lib/python3.10/multiprocessing/process.py\", line 314, in _bootstrap\n    self.run()\n", "  File \"/usr/local/lib/python3.10/site-packages/newrelic/api/background_task.py\", line 117, in wrapper\n    return wrapped(*args, **kwargs)\n", "  File \"/usr/local/lib/python3.10/site-packages/mage_ai/orchestration/queue/process_queue.py\", line 315, in run\n    start_session_and_run(args[1], *args[2], **args[3])\n", "  File \"/usr/local/lib/python3.10/site-packages/mage_ai/orchestration/db/process.py\", line 15, in start_session_and_run\n    results = target(*args)\n", "  File \"/usr/local/lib/python3.10/site-packages/mage_ai/orchestration/pipeline_scheduler_original.py\", line 1236, in run_block\n    return ExecutorFactory.get_block_executor(\n", "  File \"/usr/local/lib/python3.10/site-packages/mage_ai/data_preparation/executors/block_executor.py\", line 682, in execute\n    on_failure(\n", "  File \"/usr/local/lib/python3.10/site-packages/mage_ai/orchestration/db/__init__.py\", line 158, in func_with_rollback\n    return func(*args, **kwargs)\n", "  File \"/usr/local/lib/python3.10/site-packages/mage_ai/orchestration/pipeline_scheduler_original.py\", line 465, in on_block_failure\n    self.logger.exception(\n", "  File \"/usr/local/lib/python3.10/site-packages/mage_ai/data_preparation/logging/logger.py\", line 30, in exception\n    self.__send_message('exception', message, **kwargs)\n", "  File \"/usr/local/lib/python3.10/site-packages/mage_ai/data_preparation/logging/logger.py\", line 65, in __send_message\n    data['error_stack'] = traceback.format_stack()\n"], "error_stacktrace": "1050 (42S01): Table 'departments' already exists"}
Traceback (most recent call last):
  File "/usr/local/lib/python3.10/site-packages/mysql/connector/connection_cext.py", line 639, in cmd_query
    self._cmysql.query(
_mysql_connector.MySQLInterfaceError: Table 'departments' already exists

The above exception was the direct cause of the following exception:

Traceback (most recent call last):
  File "/usr/local/lib/python3.10/site-packages/mage_ai/data_preparation/executors/block_executor.py", line 647, in execute
    result = __execute_with_retry()
  File "/usr/local/lib/python3.10/site-packages/mage_ai/shared/retry.py", line 54, in retry_func
    raise e
  File "/usr/local/lib/python3.10/site-packages/mage_ai/shared/retry.py", line 38, in retry_func
    return func(*args, **kwargs)
  File "/usr/local/lib/python3.10/site-packages/mage_ai/data_preparation/executors/block_executor.py", line 621, in __execute_with_retry
    return self._execute(
  File "/usr/local/lib/python3.10/site-packages/mage_ai/data_preparation/executors/block_executor.py", line 1154, in _execute
    result = self.block.execute_sync(
  File "/usr/local/lib/python3.10/site-packages/mage_ai/data_preparation/models/block/__init__.py", line 1691, in execute_sync
    return __execute()
  File "/usr/local/lib/python3.10/site-packages/mage_ai/data_preparation/models/block/__init__.py", line 1668, in __execute
    raise err
  File "/usr/local/lib/python3.10/site-packages/mage_ai/data_preparation/models/block/__init__.py", line 1570, in __execute
    output = self.execute_block(
  File "/usr/local/lib/python3.10/site-packages/mage_ai/data_preparation/models/block/__init__.py", line 1910, in execute_block
    outputs = self._execute_block(
  File "/usr/local/lib/python3.10/site-packages/mage_ai/data_preparation/models/block/sql/__init__.py", line 749, in _execute_block
    return execute_sql_code(
  File "/usr/local/lib/python3.10/site-packages/mage_ai/data_preparation/models/block/sql/__init__.py", line 414, in execute_sql_code
    return execute_raw_sql(
  File "/usr/local/lib/python3.10/site-packages/mage_ai/data_preparation/models/block/sql/__init__.py", line 722, in execute_raw_sql
    results = loader.execute_queries(
  File "/usr/local/lib/python3.10/site-packages/mage_ai/io/sql.py", line 164, in execute_queries
    result = cursor.execute(query, **variables)
  File "/usr/local/lib/python3.10/site-packages/mysql/connector/cursor_cext.py", line 330, in execute
    result = self._cnx.cmd_query(
  File "/usr/local/lib/python3.10/site-packages/mysql/connector/opentelemetry/context_propagation.py", line 86, in wrapper
    result = method(cnx, *args, **kwargs)
  File "/usr/local/lib/python3.10/site-packages/mysql/connector/connection_cext.py", line 647, in cmd_query
    raise get_mysql_exception(
mysql.connector.errors.ProgrammingError: 1050 (42S01): Table 'departments' already exists
2024-09-25T08:09:11 {"block_run_id": 33, "block_uuid": "load_titles", "pipeline_run_id": 2, "pipeline_schedule_id": 1, "pipeline_uuid": "wisr_challenge_pipeline", "hostname": "d372c474b7a1", "level": "INFO", "message": "BlockRun 33 (block_uuid: load_titles) completes.", "timestamp": 1727251751.92693, "uuid": "6bb1a97cf0ea4e1a8db865b6c0018fd9"}
2024-09-25T08:09:19 {"cpu": 0.24951171875, "cpu_total": 12, "cpu_usage": 0.020792643229166668, "memory": 3616.0, "memory_total": 4845.0, "memory_usage": 0.7463364293085656, "pipeline_run_id": 2, "pipeline_schedule_id": 1, "pipeline_uuid": "wisr_challenge_pipeline", "hostname": "d372c474b7a1", "level": "INFO", "message": "Pipeline wisr_challenge_pipeline for run 2 in schedule 1 is alive.", "timestamp": 1727251759.268129, "uuid": "445e8fb966094a179604b31d59406d6b"}
